<?xml version="1.0" ?>
<!-- =================================================================================== -->
<!-- |    This document was autogenerated by xacro from allegro_hand_description_right.xacro | -->
<!-- |    EDITING THIS FILE BY HAND IS NOT RECOMMENDED                                 | -->
<!-- =================================================================================== -->
<robot name="allegro_hand_right" xmlns:xacro="http://www.ros.org/wiki/xacro">
    <!-- ======================== BASE PARAMS ========================= -->
    <!-- ======================== FINGER PARAMS ======================== -->
    <!-- full height from joint to tip. when used,
    the radius of the finger tip sphere will be subtracted
    and one fixed link will be added for the tip. -->
    <!-- ========================= THUMB PARAMS ========================= -->
    <!-- ========================= LIMITS ========================= -->
    <!-- ============================================================================= -->
    <!-- PALM -->
    <link name="world" />
    <joint name="global" type="fixed">
        <parent link="world" />
        <child link="palm_link" />
        <!--<origin xyz="0 0 0.095" rpy="0 0 0"/>-->
        <origin xyz="0 0 0.0" rpy="0 0 0" />
    </joint>
    <link name="palm_link">
        <visual>
            <geometry>
                <mesh filename="package://allegro_hand_description/meshes/body.stl" scale="0.001 0.001 0.001" />
            </geometry>
            <origin rpy="1.57 0 -1.57" xyz="0.000 0.006 -0.0472" />
            <material name="black">
                <color rgba="0.2 0.2 0.2 1" />
            </material>
        </visual>
        <collision>
            <geometry>
                <mesh filename="package://allegro_hand_description/meshes/body.stl" scale="0.001 0.001 0.001" />
            </geometry>
            <origin rpy="1.57 0 -1.57" xyz="0.000 0.006 -0.0472" />
        </collision>
        <inertial>
            <origin rpy="0 0 0" xyz="0 0 0.0475" />
            <mass value="0.4154" />
            <inertia ixx="1e-4" ixy="0.0" ixz="0.0" iyy="1e-4" iyz="0.0" izz="1e-4" />
        </inertial>
    </link>
    <!-- INDEX -->
    <link name="link_0_0">
        <visual>
            <geometry>
                <mesh filename="package://allegro_hand_description/meshes/f1.stl" scale="0.001 0.001 0.001" />
            </geometry>
            <origin rpy="3.14 0 -1.57" xyz="0.0225 -0.01575 -0.05263" />
            <material name="black">
                <color rgba="0.2 0.2 0.2 1" />
            </material>
        </visual>
        <collision>
            <geometry>
                <mesh filename="package://allegro_hand_description/meshes/f1.stl" scale="0.001 0.001 0.001" />
            </geometry>
            <origin rpy="3.14 0 -1.57" xyz="0.0225 -0.01575 -0.05263" />
        </collision>
        <inertial>
            <origin rpy="0 0 0" xyz="0 0 0.0475" />
            <mass value="0.4154" />
            <inertia ixx="1e-4" ixy="0.0" ixz="0.0" iyy="1e-4" iyz="0.0" izz="1e-4" />
        </inertial>
    </link>
    <joint name="joint_0_0" type="revolute">
        <axis xyz="0 0 1" />
        <limit effort="15" lower="-0.47" upper="0.47" velocity="7" />
        <parent link="palm_link" />
        <child link="link_0_0" />
        <origin rpy="0 0 0" xyz="0.0225 0.019447 0.006263" />
        <dynamics damping="3" friction="10" />
    </joint>
    <link name="link_1_0">
        <visual>
            <geometry>
                <mesh filename="package://allegro_hand_description/meshes/f2.stl" scale="0.001 0.001 0.001" />
            </geometry>
            <origin rpy="-1.57 0 -1.57" xyz="0.0 0 0" />
            <material name="black">
                <color rgba="0.2 0.2 0.2 1" />
            </material>
        </visual>
        <collision>
            <geometry>
                <mesh filename="package://allegro_hand_description/meshes/f2.stl" scale="0.001 0.001 0.001" />
            </geometry>
            <origin rpy="-1.57 0 -1.57" xyz="0.0 0 0" />
        </collision>
        <inertial>
            <origin rpy="0 0 0" xyz="0 0 0.0475" />
            <mass value="0.4154" />
            <inertia ixx="1e-4" ixy="0.0" ixz="0.0" iyy="1e-4" iyz="0.0" izz="1e-4" />
        </inertial>
    </link>
    <joint name="joint_1_0" type="revolute">
        <axis xyz="1 0 0" />
        <limit effort="15" lower="-0.47" upper="0.47" velocity="7" />
        <parent link="link_0_0" />
        <child link="link_1_0" />
        <origin rpy="0 0 0" xyz="0.0 0.04175 0.00" />
        <dynamics damping="3" friction="10" />
    </joint>
    <link name="link_2_0">
        <visual>
            <geometry>
                <mesh filename="package://allegro_hand_description/meshes/f3.stl" scale="0.001 0.001 0.001" />
            </geometry>
            <origin rpy="0 3.141592 1.57" xyz="0.0225 -0.05725 -0.1065" />
            <material name="black">
                <color rgba="0.2 0.2 0.2 1" />
            </material>
        </visual>
        <collision>
            <geometry>
                <mesh filename="package://allegro_hand_description/meshes/f3.stl" scale="0.001 0.001 0.001" />
            </geometry>
            <origin rpy="0 3.14 1.57" xyz="0.0225 -0.05725 -0.1065" />
        </collision>
        <inertial>
            <origin rpy="0 0 0" xyz="0 0 0.0475" />
            <mass value="0.4154" />
            <inertia ixx="1e-4" ixy="0.0" ixz="0.0" iyy="1e-4" iyz="0.0" izz="1e-4" />
        </inertial>
    </link>
    <joint name="joint_2_0" type="revolute">
        <axis xyz="1 0 0" />
        <limit effort="15" lower="-0.47" upper="0.47" velocity="7" />
        <parent link="link_1_0" />
        <child link="link_2_0" />
        <origin rpy="0 0 0" xyz="0.0 0.00 0.05425" />
        <dynamics damping="3" friction="10" />
    </joint>
    <link name="link_2_0_tip">
        <visual>
            <geometry>
                <mesh filename="package://allegro_hand_description/meshes/f4.stl" scale="0.001 0.001 0.001" />
            </geometry>
            <origin rpy="1.57 0 0" xyz="0.0005 0.0005 -0.019" />
            <material name="white">
                <color rgba="0.9 0.9 0.9 1" />
            </material>
        </visual>
        <collision>
            <geometry>
                <mesh filename="package://allegro_hand_description/meshes/f4.stl" scale="0.001 0.001 0.001" />
            </geometry>
            <origin rpy="1.57 0 0" xyz="0.0005 0.0005 -0.019" />
        </collision>
        <inertial>
            <origin rpy="0 0 0" xyz="0 0 0.0475" />
            <mass value="0.4154" />
            <inertia ixx="1e-4" ixy="0.0" ixz="0.0" iyy="1e-4" iyz="0.0" izz="1e-4" />
        </inertial>
    </link>
    <joint name="joint_2_0_tip" type="fixed">
        <axis xyz="1 0 0" />
        <limit effort="15" lower="-0.47" upper="0.47" velocity="7" />
        <parent link="link_2_0" />
        <child link="link_2_0_tip" />
        <origin rpy="0 0 0" xyz="0.0 0.00 0.05425" />
        <dynamics damping="3" friction="10" />
    </joint>
    <!-- MIDDLE -->
    <link name="link_3_0">
        <visual>
            <geometry>
                <mesh filename="package://allegro_hand_description/meshes/f1.stl" scale="0.001 0.001 0.001" />
            </geometry>
            <origin rpy="3.14 0 -1.57" xyz="0.0225 -0.01575 -0.05263" />
            <material name="black">
                <color rgba="0.2 0.2 0.2 1" />
            </material>
        </visual>
        <collision>
            <geometry>
                <mesh filename="package://allegro_hand_description/meshes/f1.stl" scale="0.001 0.001 0.001" />
            </geometry>
            <origin rpy="3.14 0 -1.57" xyz="0.0225 -0.01575 -0.05263" />
        </collision>
        <inertial>
            <origin rpy="0 0 0" xyz="0 0 0.0475" />
            <mass value="0.4154" />
            <inertia ixx="1e-4" ixy="0.0" ixz="0.0" iyy="1e-4" iyz="0.0" izz="1e-4" />
        </inertial>
    </link>
    <joint name="joint_3_0" type="revolute">
        <axis xyz="0 0 1" />
        <limit effort="15" lower="-0.47" upper="0.47" velocity="7" />
        <parent link="palm_link" />
        <child link="link_3_0" />
        <origin rpy="0 0 0" xyz="-0.0225 0.019447 0.006263" />
        <dynamics damping="3" friction="10" />
    </joint>
    <link name="link_4_0">
        <visual>
            <geometry>
                <mesh filename="package://allegro_hand_description/meshes/f2.stl" scale="0.001 0.001 0.001" />
            </geometry>
            <origin rpy="-1.57 0 -1.57" xyz="0.0 0 0" />
            <material name="black">
                <color rgba="0.2 0.2 0.2 1" />
            </material>
        </visual>
        <collision>
            <geometry>
                <mesh filename="package://allegro_hand_description/meshes/f2.stl" scale="0.001 0.001 0.001" />
            </geometry>
            <origin rpy="-1.57 0 -1.57" xyz="0.0 0 0" />
        </collision>
        <inertial>
            <origin rpy="0 0 0" xyz="0 0 0.0475" />
            <mass value="0.4154" />
            <inertia ixx="1e-4" ixy="0.0" ixz="0.0" iyy="1e-4" iyz="0.0" izz="1e-4" />
        </inertial>
    </link>
    <joint name="joint_4_0" type="revolute">
        <axis xyz="1 0 0" />
        <limit effort="15" lower="-0.47" upper="0.47" velocity="7" />
        <parent link="link_3_0" />
        <child link="link_4_0" />
        <origin rpy="0 0 0" xyz="0.0 0.04175 0.00" />
        <dynamics damping="3" friction="10" />
    </joint>
    <link name="link_5_0">
        <visual>
            <geometry>
                <mesh filename="package://allegro_hand_description/meshes/f3.stl" scale="0.001 0.001 0.001" />
            </geometry>
            <origin rpy="0 3.141592 1.57" xyz="0.0225 -0.05725 -0.1065" />
            <material name="black">
                <color rgba="0.2 0.2 0.2 1" />
            </material>
        </visual>
        <collision>
            <geometry>
                <mesh filename="package://allegro_hand_description/meshes/f3.stl" scale="0.001 0.001 0.001" />
            </geometry>
            <origin rpy="0 3.14 1.57" xyz="0.0225 -0.05725 -0.1065" />
        </collision>
        <inertial>
            <origin rpy="0 0 0" xyz="0 0 0.0475" />
            <mass value="0.4154" />
            <inertia ixx="1e-4" ixy="0.0" ixz="0.0" iyy="1e-4" iyz="0.0" izz="1e-4" />
        </inertial>
    </link>
    <joint name="joint_5_0" type="revolute">
        <axis xyz="1 0 0" />
        <limit effort="15" lower="-0.47" upper="0.47" velocity="7" />
        <parent link="link_4_0" />
        <child link="link_5_0" />
        <origin rpy="0 0 0" xyz="0.0 0.00 0.05425" />
        <dynamics damping="3" friction="10" />
    </joint>
    <link name="link_5_0_tip">
        <visual>
            <geometry>
                <mesh filename="package://allegro_hand_description/meshes/f4.stl" scale="0.001 0.001 0.001" />
            </geometry>
            <origin rpy="1.57 0 0" xyz="0.0005 0.0005 -0.019" />
            <material name="white">
                <color rgba="0.9 0.9 0.9 1" />
            </material>
        </visual>
        <collision>
            <geometry>
                <mesh filename="package://allegro_hand_description/meshes/f4.stl" scale="0.001 0.001 0.001" />
            </geometry>
            <origin rpy="1.57 0 0" xyz="0.0005 0.0005 -0.019" />
        </collision>
        <inertial>
            <origin rpy="0 0 0" xyz="0 0 0.0475" />
            <mass value="0.4154" />
            <inertia ixx="1e-4" ixy="0.0" ixz="0.0" iyy="1e-4" iyz="0.0" izz="1e-4" />
        </inertial>
    </link>
    <joint name="joint_5_0_tip" type="fixed">
        <axis xyz="1 0 0" />
        <limit effort="15" lower="-0.47" upper="0.47" velocity="7" />
        <parent link="link_5_0" />
        <child link="link_5_0_tip" />
        <origin rpy="0 0 0" xyz="0.0 0.00 0.05425" />
        <dynamics damping="3" friction="10" />
    </joint>
    <!-- THUMB -->
    <link name="link_6_0">
        <visual>
            <geometry>
                <mesh filename="package://allegro_hand_description/meshes/f1.stl" scale="0.001 0.001 0.001" />
            </geometry>
            <origin rpy="3.14 0 -1.57" xyz="0.0225 -0.01575 -0.05263" />
            <material name="black">
                <color rgba="0.2 0.2 0.2 1" />
            </material>
        </visual>
        <collision>
            <geometry>
                <mesh filename="package://allegro_hand_description/meshes/f1.stl" scale="0.001 0.001 0.001" />
            </geometry>
            <origin rpy="3.14 0 -1.57" xyz="0.0225 -0.01575 -0.05263" />
        </collision>
        <inertial>
            <origin rpy="0 0 0" xyz="0 0 0.0475" />
            <mass value="0.4154" />
            <inertia ixx="1e-4" ixy="0.0" ixz="0.0" iyy="1e-4" iyz="0.0" izz="1e-4" />
        </inertial>
    </link>
    <joint name="joint_6_0" type="revolute">
        <axis xyz="0 0 1" />
        <limit effort="15" lower="-0.47" upper="0.47" velocity="7" />
        <parent link="palm_link" />
        <child link="link_6_0" />
        <origin rpy="0 0 3.14" xyz="0 -0.019447 0.006263" />
        <dynamics damping="3" friction="10" />
    </joint>
    <link name="link_7_0">
        <visual>
            <geometry>
                <mesh filename="package://allegro_hand_description/meshes/f2.stl" scale="0.001 0.001 0.001" />
            </geometry>
            <origin rpy="-1.57 0 -1.57" xyz="0.0 0 0" />
            <material name="black">
                <color rgba="0.2 0.2 0.2 1" />
            </material>
        </visual>
        <collision>
            <geometry>
                <mesh filename="package://allegro_hand_description/meshes/f2.stl" scale="0.001 0.001 0.001" />
            </geometry>
            <origin rpy="-1.57 0 -1.57" xyz="0.0 0 0" />
        </collision>
        <inertial>
            <origin rpy="0 0 0" xyz="0 0 0.0475" />
            <mass value="0.4154" />
            <inertia ixx="1e-4" ixy="0.0" ixz="0.0" iyy="1e-4" iyz="0.0" izz="1e-4" />
        </inertial>
    </link>
    <joint name="joint_7_0" type="revolute">
        <axis xyz="1 0 0" />
        <limit effort="15" lower="-0.47" upper="0.47" velocity="7" />
        <parent link="link_6_0" />
        <child link="link_7_0" />
        <origin rpy="0 0 0" xyz="0.0 0.04175 0.00" />
        <dynamics damping="3" friction="10" />
    </joint>
    <link name="link_8_0">
        <visual>
            <geometry>
                <mesh filename="package://allegro_hand_description/meshes/f3.stl" scale="0.001 0.001 0.001" />
            </geometry>
            <origin rpy="0 3.141592 1.57" xyz="0.0225 -0.05725 -0.1065" />
            <material name="black">
                <color rgba="0.2 0.2 0.2 1" />
            </material>
        </visual>
        <collision>
            <geometry>
                <mesh filename="package://allegro_hand_description/meshes/f3.stl" scale="0.001 0.001 0.001" />
            </geometry>
            <origin rpy="0 3.14 1.57" xyz="0.0225 -0.05725 -0.1065" />
        </collision>
        <inertial>
            <origin rpy="0 0 0" xyz="0 0 0.0475" />
            <mass value="0.4154" />
            <inertia ixx="1e-4" ixy="0.0" ixz="0.0" iyy="1e-4" iyz="0.0" izz="1e-4" />
        </inertial>
    </link>
    <joint name="joint_8_0" type="revolute">
        <axis xyz="1 0 0" />
        <limit effort="15" lower="-0.47" upper="0.47" velocity="7" />
        <parent link="link_7_0" />
        <child link="link_8_0" />
        <origin rpy="0 0 0" xyz="0.0 0.00 0.05425" />
        <dynamics damping="3" friction="10" />
    </joint>
    <link name="link_8_0_tip">
        <visual>
            <geometry>
                <mesh filename="package://allegro_hand_description/meshes/f4.stl" scale="0.001 0.001 0.001" />
            </geometry>
            <origin rpy="1.57 0 0" xyz="0.0005 0.0005 -0.019" />
            <material name="white">
                <color rgba="0.9 0.9 0.9 1" />
            </material>
        </visual>
        <collision>
            <geometry>
                <mesh filename="package://allegro_hand_description/meshes/f4.stl" scale="0.001 0.001 0.001" />
            </geometry>
            <origin rpy="1.57 0 0" xyz="0.0005 0.0005 -0.019" />
        </collision>
        <inertial>
            <origin rpy="0 0 0" xyz="0 0 0.0475" />
            <mass value="0.4154" />
            <inertia ixx="1e-4" ixy="0.0" ixz="0.0" iyy="1e-4" iyz="0.0" izz="1e-4" />
        </inertial>
    </link>
    <joint name="joint_8_0_tip" type="fixed">
        <axis xyz="1 0 0" />
        <limit effort="15" lower="-0.47" upper="0.47" velocity="7" />
        <parent link="link_8_0" />
        <child link="link_8_0_tip" />
        <origin rpy="0 0 0" xyz="0.0 0.00 0.05425" />
        <dynamics damping="3" friction="10" />
    </joint>
    <transmission name="trans_joint_0_0">
        <type>transmission_interface/SimpleTransmission</type>
        <joint name="joint_0_0">
            <hardwareInterface>hardware_interface/EffortJointInterface</hardwareInterface>
        </joint>
        <actuator name="joint_0_0_motor">
            <hardwareInterface>hardware_interface/EffortJointInterface</hardwareInterface>
            <mechanicalReduction>1</mechanicalReduction>
        </actuator>
    </transmission>
    <transmission name="trans_joint_1_0">
        <type>transmission_interface/SimpleTransmission</type>
        <joint name="joint_1_0">
            <hardwareInterface>hardware_interface/EffortJointInterface</hardwareInterface>
        </joint>
        <actuator name="joint_1_0_motor">
            <hardwareInterface>hardware_interface/EffortJointInterface</hardwareInterface>
            <mechanicalReduction>1</mechanicalReduction>
        </actuator>
    </transmission>
    <transmission name="trans_joint_2_0">
        <type>transmission_interface/SimpleTransmission</type>
        <joint name="joint_2_0">
            <hardwareInterface>hardware_interface/EffortJointInterface</hardwareInterface>
        </joint>
        <actuator name="joint_2_0_motor">
            <hardwareInterface>hardware_interface/EffortJointInterface</hardwareInterface>
            <mechanicalReduction>1</mechanicalReduction>
        </actuator>
    </transmission>
    <transmission name="trans_joint_3_0">
        <type>transmission_interface/SimpleTransmission</type>
        <joint name="joint_3_0">
            <hardwareInterface>hardware_interface/EffortJointInterface</hardwareInterface>
        </joint>
        <actuator name="joint_3_0_motor">
            <hardwareInterface>hardware_interface/EffortJointInterface</hardwareInterface>
            <mechanicalReduction>1</mechanicalReduction>
        </actuator>
    </transmission>
    <transmission name="trans_joint_4_0">
        <type>transmission_interface/SimpleTransmission</type>
        <joint name="joint_4_0">
            <hardwareInterface>hardware_interface/EffortJointInterface</hardwareInterface>
        </joint>
        <actuator name="joint_4_0_motor">
            <hardwareInterface>hardware_interface/EffortJointInterface</hardwareInterface>
            <mechanicalReduction>1</mechanicalReduction>
        </actuator>
    </transmission>
    <transmission name="trans_joint_5_0">
        <type>transmission_interface/SimpleTransmission</type>
        <joint name="joint_5_0">
            <hardwareInterface>hardware_interface/EffortJointInterface</hardwareInterface>
        </joint>
        <actuator name="joint_5_0_motor">
            <hardwareInterface>hardware_interface/EffortJointInterface</hardwareInterface>
            <mechanicalReduction>1</mechanicalReduction>
        </actuator>
    </transmission>
    <transmission name="trans_joint_6_0">
        <type>transmission_interface/SimpleTransmission</type>
        <joint name="joint_6_0">
            <hardwareInterface>hardware_interface/EffortJointInterface</hardwareInterface>
        </joint>
        <actuator name="joint_6_0_motor">
            <hardwareInterface>hardware_interface/EffortJointInterface</hardwareInterface>
            <mechanicalReduction>1</mechanicalReduction>
        </actuator>
    </transmission>
    <transmission name="trans_joint_7_0">
        <type>transmission_interface/SimpleTransmission</type>
        <joint name="joint_7_0">
            <hardwareInterface>hardware_interface/EffortJointInterface</hardwareInterface>
        </joint>
        <actuator name="joint_7_0_motor">
            <hardwareInterface>hardware_interface/EffortJointInterface</hardwareInterface>
            <mechanicalReduction>1</mechanicalReduction>
        </actuator>
    </transmission>
    <transmission name="trans_joint_8_0">
        <type>transmission_interface/SimpleTransmission</type>
        <joint name="joint_8_0">
            <hardwareInterface>hardware_interface/EffortJointInterface</hardwareInterface>
        </joint>
        <actuator name="joint_8_0_motor">
            <hardwareInterface>hardware_interface/EffortJointInterface</hardwareInterface>
            <mechanicalReduction>1</mechanicalReduction>
        </actuator>
    </transmission>
    <gazebo>
        <plugin name="gazebo_ros_control" filename="libgazebo_ros_control.so">
            <robotNamespace>/</robotNamespace>
        </plugin>
    </gazebo>
</robot>

