<mujoco model="fr3v2">
  <compiler angle="radian" meshdir="assets"/>


  <worldbody>
    <body name="right_base" childclass="fr3v2" pos ="0 0 0.3">
      <body name="fr3v2_right_link0">
        <geom mesh="link0_0" material="black" class="visual"/>
        <geom mesh="link0_1" material="white" class="visual"/>
        <geom mesh="link0_2" material="white" class="visual"/>
        <geom mesh="link0_3" material="white" class="visual"/>
        <geom mesh="link0_4" material="white" class="visual"/>
        <geom mesh="link0_5" material="red" class="visual"/>
        <geom name="fr3v2_right_link0_collision" mesh="link0_coll" class="collision"/>
        <inertial pos="-0.0172 0.0004 0.0745" quat="0.661377 -0.250161 -0.250161 0.661377" mass="3.85"
          diaginertia="0.0115 0.0107656 0.00673444"/>
        <body name="fr3v2_right_link1" pos="0 0 0.333">
          <inertial pos="-0.00458 0.027016 -0.0618" quat="0.989811 0.110789 0.00992127 0.0888923" mass="2.4377"
            diaginertia="0.0233003 0.0222611 0.00463865"/>
          <joint name="right_joint1" pos="0 0 0" axis="0 0 1" range="-2.7437 2.7437" actuatorfrcrange="-87 87"
            damping="0.003" frictionloss="0.2"/>
          <geom name="fr3v2_right_link1_collision" class="collision" mesh="link1_coll"/>
          <geom mesh="link1_3" material="white" class="visual"/>
          <body name="fr3v2_right_link2" quat="0.707107 -0.707107 0 0">
            <inertial pos="-0.003473 -0.168509 -0.010479" quat="0.644329 0.758803 -0.0323054 0.0895283" mass="2.2375"
              diaginertia="0.0192001 0.0173406 0.0052593"/>
            <joint name="right_joint2" pos="0 0 0" axis="0 0 1" range="-1.7837 1.7837" actuatorfrcrange="-87 87"
              damping="0.003" frictionloss="0.2"/>
            <geom name="fr3v2_right_link2_collision" class="collision" mesh="link2_coll"/>
            <geom mesh="link2_3" material="white" class="visual"/>
            <body name="fr3v2_right_link3" pos="0 -0.316 0" quat="0.707107 0.707107 0 0">
              <inertial pos="0.092968 0.01801 0.033533" quat="0.877348 -0.0280595 -0.265819 0.398514" mass="2.18579"
                diaginertia="0.0146052 0.0104212 0.00447362"/>
              <joint name="right_joint3" pos="0 0 0" axis="0 0 1" range="-2.9007 2.9007" actuatorfrcrange="-87 87"
                damping="0.003" frictionloss="0.2"/>
              <geom name="right_link3_collision" class="collision" mesh="link3_coll"/>
              <geom mesh="link3_3" material="white" class="visual"/>
              <body name="right_link4" pos="0.0825 0 0" quat="0.707107 0.707107 0 0">
                <inertial pos="-0.068745 0.092947 0.011195" quat="0.725019 0.567552 -0.379628 -0.0900828" mass="2.17587"
                  diaginertia="0.0126388 0.00973606 0.00442618"/>
                <joint name="right_joint4" pos="0 0 0" axis="0 0 1" range="-3.0421 -0.1518" actuatorfrcrange="-87 87"
                  damping="0.003" frictionloss="0.2"/>
                <geom name="right_link4_collision" class="collision" mesh="link4_coll"/>
                <geom mesh="link4_3" material="white" class="visual"/>
                <body name="right_link5" pos="-0.0825 0.384 0" quat="0.707107 -0.707107 0 0">
                  <inertial pos="-0.004197 0.010257 -0.058103" quat="0.993747 -0.0901363 0.0101557 0.0651102"
                    mass="2.17482" diaginertia="0.0318998 0.0305191 0.0038801"/>
                  <joint name="right_joint5" pos="0 0 0" axis="0 0 1" range="-2.8065 2.8065" actuatorfrcrange="-12 12"
                    damping="0.003" frictionloss="0.2"/>
                  <geom name="right_link5_collision" class="collision" mesh="link5_coll"/>
                  <geom mesh="link5_3" material="white" class="visual"/>
                  <body name="right_link6" quat="0.707107 0.707107 0 0">
                    <inertial pos="0.070958 -0.014137 -0.035324" quat="-0.141552 0.574736 0.130817 0.795317"
                      mass="1.56762" diaginertia="0.0047496 0.0041461 0.0024043"/>
                    <joint name="right_joint6" pos="0 0 0" axis="0 0 1" range="0.5445 4.5169" actuatorfrcrange="-12 12"
                      damping="0.003" frictionloss="0.2"/>
                    <geom name="fr3v2_right_link6_collision" class="collision" mesh="link6_coll"/>
                    <geom mesh="link6_0" material="gray" class="visual"/>
                    <geom mesh="link6_1" material="white" class="visual"/>
                    <geom mesh="link6_2" material="white" class="visual"/>
                    <geom mesh="link6_3" material="gray" class="visual"/>
                    <geom mesh="link6_4" material="button_red" class="visual"/>
                    <geom mesh="link6_5" material="button_red" class="visual"/>
                    <geom mesh="link6_6" material="black" class="visual"/>
                    <geom mesh="link6_7" material="white" class="visual"/>
                    <geom mesh="link6_8" material="button_red" class="visual"/>
                    <geom mesh="link6_9" material="white" class="visual"/>
                    <body name="fr3v2_right_link7" pos="0.088 0 0" quat="0.707107 0.707107 0 0">
                      <inertial pos="0.008204 0.001156 0.061016" quat="0.70836 0.00347393 0.0424735 0.704564"
                        mass="0.682876" diaginertia="0.00110022 0.000899844 0.000699938"/>
                      <joint name="right_joint7" pos="0 0 0" axis="0 0 1" range="-3.0159 3.0159"
                        actuatorfrcrange="-12 12" damping="0.003" frictionloss="0.2"/>
                      <geom name="fr3v2_right_link7_collision" class="collision" mesh="link7_coll"/>
                      <geom mesh="link7_0" material="white" class="visual"/>
                      <geom mesh="link7_1" material="white" class="visual"/>
                      <geom mesh="link7_2" material="white" class="visual"/>
                      <geom mesh="link7_3" material="white" class="visual"/>
                      <geom mesh="link7_4" material="white" class="visual"/>
                      <geom mesh="link7_5" material="white" class="visual"/>
                      <geom mesh="link7_6" material="white" class="visual"/>
                      <body name="fr3v2_right_link8" pos="0 0 0.107"/>
                    </body>
                  </body>
                </body>
              </body>
            </body>
          </body>
        </body>
      </body>
    </body>
  </worldbody>

  <actuator>
    <position class="fr3v2" name="right_joint1" joint="right_joint1" kp="4500" kv="450"/>
    <position class="fr3v2" name="right_joint2" joint="right_joint2" kp="4500" kv="450"/>
    <position class="fr3v2" name="right_joint3" joint="right_joint3" kp="3500" kv="350"/>
    <position class="fr3v2" name="right_joint4" joint="right_joint4" kp="3500" kv="350"/>
    <position class="fr3v2" name="right_joint5" joint="right_joint5" kp="2000" kv="200"/>
    <position class="fr3v2" name="right_joint6" joint="right_joint6" kp="2000" kv="200"/>
    <position class="fr3v2" name="right_joint7" joint="right_joint7" kp="2000" kv="200"/>
  </actuator>

  <keyframe>
    <key name="right_home" qpos="0 0 0 -1.57079 0 1.57079 -0.7853" ctrl="0 0 0 -1.57079 0 1.57079 -0.7853"/>
  </keyframe>
</mujoco>
